[2023-12-12T09:20:28.727+0000] {taskinstance.py:1159} INFO - Dependencies all met for dep_context=non-requeueable deps ti=<TaskInstance: my_bipo_dag.call_api_and_process scheduled__2023-01-20T00:00:00+00:00 [queued]>
[2023-12-12T09:20:28.746+0000] {taskinstance.py:1159} INFO - Dependencies all met for dep_context=requeueable deps ti=<TaskInstance: my_bipo_dag.call_api_and_process scheduled__2023-01-20T00:00:00+00:00 [queued]>
[2023-12-12T09:20:28.747+0000] {taskinstance.py:1361} INFO - Starting attempt 1 of 2
[2023-12-12T09:20:28.771+0000] {taskinstance.py:1382} INFO - Executing <Task(PythonOperator): call_api_and_process> on 2023-01-20 00:00:00+00:00
[2023-12-12T09:20:28.780+0000] {standard_task_runner.py:57} INFO - Started process 3611 to run task
[2023-12-12T09:20:28.784+0000] {standard_task_runner.py:84} INFO - Running: ['***', 'tasks', 'run', 'my_bipo_dag', 'call_api_and_process', 'scheduled__2023-01-20T00:00:00+00:00', '--job-id', '207', '--raw', '--subdir', 'DAGS_FOLDER/bipo_employee_info.py', '--cfg-path', '/tmp/tmpvczbnq7v']
[2023-12-12T09:20:28.787+0000] {standard_task_runner.py:85} INFO - Job 207: Subtask call_api_and_process
[2023-12-12T09:20:28.807+0000] {logging_mixin.py:154} WARNING - /home/***/.local/lib/python3.8/site-packages/***/settings.py:195 DeprecationWarning: The sql_alchemy_conn option in [core] has been moved to the sql_alchemy_conn option in [database] - the old setting has been used, but please update your config.
[2023-12-12T09:20:28.847+0000] {task_command.py:416} INFO - Running <TaskInstance: my_bipo_dag.call_api_and_process scheduled__2023-01-20T00:00:00+00:00 [running]> on host e1a26a98da8f
[2023-12-12T09:20:28.963+0000] {taskinstance.py:1662} INFO - Exporting env vars: AIRFLOW_CTX_DAG_OWNER='***' AIRFLOW_CTX_DAG_ID='my_bipo_dag' AIRFLOW_CTX_TASK_ID='call_api_and_process' AIRFLOW_CTX_EXECUTION_DATE='2023-01-20T00:00:00+00:00' AIRFLOW_CTX_TRY_NUMBER='1' AIRFLOW_CTX_DAG_RUN_ID='scheduled__2023-01-20T00:00:00+00:00'
[2023-12-12T09:25:01.738+0000] {local_task_job_runner.py:294} WARNING - State of this instance has been externally set to None. Terminating instance.
[2023-12-12T09:25:01.740+0000] {process_utils.py:131} INFO - Sending 15 to group 3611. PIDs of all processes in the group: [3611]
[2023-12-12T09:25:01.741+0000] {process_utils.py:86} INFO - Sending the signal 15 to group 3611
[2023-12-12T09:25:01.741+0000] {taskinstance.py:1632} ERROR - Received SIGTERM. Terminating subprocesses.
[2023-12-12T09:25:01.754+0000] {taskinstance.py:1937} ERROR - Task failed with exception
Traceback (most recent call last):
  File "/home/airflow/.local/lib/python3.8/site-packages/airflow/operators/python.py", line 192, in execute
    return_value = self.execute_callable()
  File "/home/airflow/.local/lib/python3.8/site-packages/airflow/operators/python.py", line 209, in execute_callable
    return self.python_callable(*self.op_args, **self.op_kwargs)
  File "/opt/airflow/dags/bipo_employee_info.py", line 57, in call_api_and_process
    response = requests.post(api_url, headers=headers, json=body)
  File "/home/airflow/.local/lib/python3.8/site-packages/requests/api.py", line 115, in post
    return request("post", url, data=data, json=json, **kwargs)
  File "/home/airflow/.local/lib/python3.8/site-packages/requests/api.py", line 59, in request
    return session.request(method=method, url=url, **kwargs)
  File "/home/airflow/.local/lib/python3.8/site-packages/requests/sessions.py", line 589, in request
    resp = self.send(prep, **send_kwargs)
  File "/home/airflow/.local/lib/python3.8/site-packages/requests/sessions.py", line 747, in send
    r.content
  File "/home/airflow/.local/lib/python3.8/site-packages/requests/models.py", line 899, in content
    self._content = b"".join(self.iter_content(CONTENT_CHUNK_SIZE)) or b""
  File "/home/airflow/.local/lib/python3.8/site-packages/requests/models.py", line 816, in generate
    yield from self.raw.stream(chunk_size, decode_content=True)
  File "/home/airflow/.local/lib/python3.8/site-packages/urllib3/response.py", line 628, in stream
    data = self.read(amt=amt, decode_content=decode_content)
  File "/home/airflow/.local/lib/python3.8/site-packages/urllib3/response.py", line 567, in read
    data = self._fp_read(amt) if not fp_closed else b""
  File "/home/airflow/.local/lib/python3.8/site-packages/urllib3/response.py", line 533, in _fp_read
    return self._fp.read(amt) if amt is not None else self._fp.read()
  File "/usr/local/lib/python3.8/http/client.py", line 459, in read
    n = self.readinto(b)
  File "/usr/local/lib/python3.8/http/client.py", line 503, in readinto
    n = self.fp.readinto(b)
  File "/usr/local/lib/python3.8/socket.py", line 669, in readinto
    return self._sock.recv_into(b)
  File "/usr/local/lib/python3.8/ssl.py", line 1274, in recv_into
    return self.read(nbytes, buffer)
  File "/usr/local/lib/python3.8/ssl.py", line 1132, in read
    return self._sslobj.read(len, buffer)
  File "/home/airflow/.local/lib/python3.8/site-packages/airflow/models/taskinstance.py", line 1634, in signal_handler
    raise AirflowException("Task received SIGTERM signal")
airflow.exceptions.AirflowException: Task received SIGTERM signal
[2023-12-12T09:25:01.764+0000] {taskinstance.py:1400} INFO - Marking task as FAILED. dag_id=my_bipo_dag, task_id=call_api_and_process, execution_date=20230120T000000, start_date=20231212T092028, end_date=20231212T092501
[2023-12-12T09:25:01.779+0000] {standard_task_runner.py:104} ERROR - Failed to execute job 207 for task call_api_and_process ((psycopg2.errors.ForeignKeyViolation) insert or update on table "task_fail" violates foreign key constraint "task_fail_ti_fkey"
DETAIL:  Key (dag_id, task_id, run_id, map_index)=(my_bipo_dag, call_api_and_process, scheduled__2023-01-20T00:00:00+00:00, -1) is not present in table "task_instance".

[SQL: INSERT INTO task_fail (task_id, dag_id, run_id, map_index, start_date, end_date, duration) VALUES (%(task_id)s, %(dag_id)s, %(run_id)s, %(map_index)s, %(start_date)s, %(end_date)s, %(duration)s) RETURNING task_fail.id]
[parameters: {'task_id': 'call_api_and_process', 'dag_id': 'my_bipo_dag', 'run_id': 'scheduled__2023-01-20T00:00:00+00:00', 'map_index': -1, 'start_date': datetime.datetime(2023, 12, 12, 9, 20, 28, 728858, tzinfo=Timezone('UTC')), 'end_date': datetime.datetime(2023, 12, 12, 9, 25, 1, 764419, tzinfo=Timezone('UTC')), 'duration': 273}]
(Background on this error at: https://sqlalche.me/e/14/gkpj); 3611)
[2023-12-12T09:25:01.794+0000] {process_utils.py:79} INFO - Process psutil.Process(pid=3611, status='terminated', exitcode=1, started='09:20:28') (3611) terminated with exit code 1
