[2023-12-11T11:13:13.343+0000] {taskinstance.py:1159} INFO - Dependencies all met for dep_context=non-requeueable deps ti=<TaskInstance: dag_email_notification.simple_failed_bash_task manual__2023-12-11T11:13:12.233059+00:00 [queued]>
[2023-12-11T11:13:13.354+0000] {taskinstance.py:1159} INFO - Dependencies all met for dep_context=requeueable deps ti=<TaskInstance: dag_email_notification.simple_failed_bash_task manual__2023-12-11T11:13:12.233059+00:00 [queued]>
[2023-12-11T11:13:13.355+0000] {taskinstance.py:1361} INFO - Starting attempt 1 of 2
[2023-12-11T11:13:13.371+0000] {taskinstance.py:1382} INFO - Executing <Task(BashOperator): simple_failed_bash_task> on 2023-12-11 11:13:12.233059+00:00
[2023-12-11T11:13:13.374+0000] {standard_task_runner.py:57} INFO - Started process 2628 to run task
[2023-12-11T11:13:13.376+0000] {standard_task_runner.py:84} INFO - Running: ['***', 'tasks', 'run', 'dag_email_notification', 'simple_failed_bash_task', 'manual__2023-12-11T11:13:12.233059+00:00', '--job-id', '42', '--raw', '--subdir', 'DAGS_FOLDER/email_notification.py', '--cfg-path', '/tmp/tmp1q4iy69e']
[2023-12-11T11:13:13.378+0000] {standard_task_runner.py:85} INFO - Job 42: Subtask simple_failed_bash_task
[2023-12-11T11:13:13.392+0000] {logging_mixin.py:154} WARNING - /home/***/.local/lib/python3.8/site-packages/***/settings.py:195 DeprecationWarning: The sql_alchemy_conn option in [core] has been moved to the sql_alchemy_conn option in [database] - the old setting has been used, but please update your config.
[2023-12-11T11:13:13.428+0000] {task_command.py:416} INFO - Running <TaskInstance: dag_email_notification.simple_failed_bash_task manual__2023-12-11T11:13:12.233059+00:00 [running]> on host e1a26a98da8f
[2023-12-11T11:13:13.507+0000] {taskinstance.py:1662} INFO - Exporting env vars: AIRFLOW_CTX_DAG_EMAIL='hai.vo@pizza4ps.com' AIRFLOW_CTX_DAG_OWNER='***' AIRFLOW_CTX_DAG_ID='dag_email_notification' AIRFLOW_CTX_TASK_ID='simple_failed_bash_task' AIRFLOW_CTX_EXECUTION_DATE='2023-12-11T11:13:12.233059+00:00' AIRFLOW_CTX_TRY_NUMBER='1' AIRFLOW_CTX_DAG_RUN_ID='manual__2023-12-11T11:13:12.233059+00:00'
[2023-12-11T11:13:13.510+0000] {subprocess.py:63} INFO - Tmp dir root location: /tmp
[2023-12-11T11:13:13.511+0000] {subprocess.py:75} INFO - Running command: ['/bin/bash', '-c', 'cd non_exist_folder']
[2023-12-11T11:13:13.522+0000] {subprocess.py:86} INFO - Output:
[2023-12-11T11:13:13.524+0000] {subprocess.py:93} INFO - /bin/bash: line 1: cd: non_exist_folder: No such file or directory
[2023-12-11T11:13:13.525+0000] {subprocess.py:97} INFO - Command exited with return code 1
[2023-12-11T11:13:13.536+0000] {taskinstance.py:1937} ERROR - Task failed with exception
Traceback (most recent call last):
  File "/home/airflow/.local/lib/python3.8/site-packages/airflow/operators/bash.py", line 210, in execute
    raise AirflowException(
airflow.exceptions.AirflowException: Bash command failed. The command returned a non-zero exit code 1.
[2023-12-11T11:13:13.539+0000] {taskinstance.py:1400} INFO - Marking task as UP_FOR_RETRY. dag_id=dag_email_notification, task_id=simple_failed_bash_task, execution_date=20231211T111312, start_date=20231211T111313, end_date=20231211T111313
[2023-12-11T11:13:13.555+0000] {logging_mixin.py:154} WARNING - /home/***/.local/lib/python3.8/site-packages/***/utils/email.py:154 RemovedInAirflow3Warning: Fetching SMTP credentials from configuration variables will be deprecated in a future release. Please set credentials using a connection instead.
[2023-12-11T11:13:13.555+0000] {configuration.py:1050} WARNING - section/key [smtp/smtp_user] not found in config
[2023-12-11T11:13:13.556+0000] {email.py:270} INFO - Email alerting: attempt 1
[2023-12-11T11:13:13.566+0000] {configuration.py:1050} WARNING - section/key [smtp/smtp_user] not found in config
[2023-12-11T11:13:13.567+0000] {email.py:270} INFO - Email alerting: attempt 1
[2023-12-11T11:13:13.568+0000] {taskinstance.py:2007} ERROR - Failed to send email to: ['hai.vo@pizza4ps.com']
Traceback (most recent call last):
  File "/home/airflow/.local/lib/python3.8/site-packages/airflow/models/taskinstance.py", line 1518, in _run_raw_task
    self._execute_task_with_callbacks(context, test_mode, session=session)
  File "/home/airflow/.local/lib/python3.8/site-packages/airflow/models/taskinstance.py", line 1681, in _execute_task_with_callbacks
    result = self._execute_task(context, task_orig)
  File "/home/airflow/.local/lib/python3.8/site-packages/airflow/models/taskinstance.py", line 1744, in _execute_task
    result = execute_callable(context=context, **execute_callable_kwargs)
  File "/home/airflow/.local/lib/python3.8/site-packages/airflow/operators/bash.py", line 210, in execute
    raise AirflowException(
airflow.exceptions.AirflowException: Bash command failed. The command returned a non-zero exit code 1.

During handling of the above exception, another exception occurred:

Traceback (most recent call last):
  File "/home/airflow/.local/lib/python3.8/site-packages/airflow/models/taskinstance.py", line 2420, in email_alert
    send_email(task.email, subject, html_content)
  File "/home/airflow/.local/lib/python3.8/site-packages/airflow/utils/email.py", line 80, in send_email
    return backend(
  File "/home/airflow/.local/lib/python3.8/site-packages/airflow/utils/email.py", line 154, in send_email_smtp
    send_mime_email(e_from=mail_from, e_to=recipients, mime_msg=msg, conn_id=conn_id, dryrun=dryrun)
  File "/home/airflow/.local/lib/python3.8/site-packages/airflow/utils/email.py", line 272, in send_mime_email
    smtp_conn = _get_smtp_connection(smtp_host, smtp_port, smtp_timeout, smtp_ssl)
  File "/home/airflow/.local/lib/python3.8/site-packages/airflow/utils/email.py", line 316, in _get_smtp_connection
    return smtplib.SMTP(host=host, port=port, timeout=timeout)
  File "/usr/local/lib/python3.8/smtplib.py", line 255, in __init__
    (code, msg) = self.connect(host, port)
  File "/usr/local/lib/python3.8/smtplib.py", line 339, in connect
    self.sock = self._get_socket(host, port, self.timeout)
  File "/usr/local/lib/python3.8/smtplib.py", line 310, in _get_socket
    return socket.create_connection((host, port), timeout,
  File "/usr/local/lib/python3.8/socket.py", line 808, in create_connection
    raise err
  File "/usr/local/lib/python3.8/socket.py", line 796, in create_connection
    sock.connect(sa)
OSError: [Errno 99] Cannot assign requested address

During handling of the above exception, another exception occurred:

Traceback (most recent call last):
  File "/home/airflow/.local/lib/python3.8/site-packages/airflow/models/taskinstance.py", line 2005, in handle_failure
    self.email_alert(error, task)
  File "/home/airflow/.local/lib/python3.8/site-packages/airflow/models/taskinstance.py", line 2422, in email_alert
    send_email(task.email, subject, html_content_err)
  File "/home/airflow/.local/lib/python3.8/site-packages/airflow/utils/email.py", line 80, in send_email
    return backend(
  File "/home/airflow/.local/lib/python3.8/site-packages/airflow/utils/email.py", line 154, in send_email_smtp
    send_mime_email(e_from=mail_from, e_to=recipients, mime_msg=msg, conn_id=conn_id, dryrun=dryrun)
  File "/home/airflow/.local/lib/python3.8/site-packages/airflow/utils/email.py", line 272, in send_mime_email
    smtp_conn = _get_smtp_connection(smtp_host, smtp_port, smtp_timeout, smtp_ssl)
  File "/home/airflow/.local/lib/python3.8/site-packages/airflow/utils/email.py", line 316, in _get_smtp_connection
    return smtplib.SMTP(host=host, port=port, timeout=timeout)
  File "/usr/local/lib/python3.8/smtplib.py", line 255, in __init__
    (code, msg) = self.connect(host, port)
  File "/usr/local/lib/python3.8/smtplib.py", line 339, in connect
    self.sock = self._get_socket(host, port, self.timeout)
  File "/usr/local/lib/python3.8/smtplib.py", line 310, in _get_socket
    return socket.create_connection((host, port), timeout,
  File "/usr/local/lib/python3.8/socket.py", line 808, in create_connection
    raise err
  File "/usr/local/lib/python3.8/socket.py", line 796, in create_connection
    sock.connect(sa)
OSError: [Errno 99] Cannot assign requested address
[2023-12-11T11:13:13.583+0000] {standard_task_runner.py:104} ERROR - Failed to execute job 42 for task simple_failed_bash_task (Bash command failed. The command returned a non-zero exit code 1.; 2628)
[2023-12-11T11:13:13.589+0000] {local_task_job_runner.py:228} INFO - Task exited with return code 1
[2023-12-11T11:13:13.605+0000] {taskinstance.py:2778} INFO - 0 downstream tasks scheduled from follow-on schedule check
